Workbook

Sheet Trường hợp kiểm thử
A1: TEST CASE SYSTEM SPRINT 1
A3: Tên dự án | B3: CoffeeGo-Nền tảng đặt bàn quán cà phê tích hợp AI Assistant và thanh toán điện tử
A4: STT | B4: Chức năng | C4: Sheet Name | D4: Số lượng test | E4: Mô tả
A5: 1 | B5: Đăng nhập | C5: Đăng nhập | D5: ='Đăng nhập'!B4 -> 19
A6: 2 | B6: Đăng ký | C6: Đăng ký | D6: ='Đăng ký '!B4 -> 19
A7: 3 | B7: Quên mật khẩu | C7: Quên mật khẩu | D7: ='Quên mật khẩu'!B4 -> 13
A8: 4 | B8: Đổi mật khẩu | C8: Đổi mật khẩu | D8: ='Đổi mật khẩu'!B4 -> 17
A9: 5 | B9: Quản lý người dùng | C9: Danh sách người dùng | D9: ='Danh sách người dùng'!B4 -> 13
C10: Phân quyền người dùng | D10: ='Phân quyền người dùng'!B4 -> 9
A11: 6 | B11: Quản lý loại bài viết | C11: Danh sách danh mục bài viết | D11: ='Danh sách danh mục bài viết'!B4 -> 12
C12: Thêm danh mục bài viết | D12: ='Thêm danh mục bài viết'!B4 -> 13
C13: Chỉnh sửa danh mục bài viết | D13: ='Chỉnh sửa danh mục bài viết'!B4 -> 12
A14: 7 | B14: Quản lý bài viết | C14: Danh sách bài viết | D14: ='Danh sách bài viết'!B4 -> 15
C15: Thêm bài viết | D15: ='Thêm bài viết'!B4 -> 19
C16: Chỉnh sửa bài viết | D16: ='Chỉnh sửa bài viết'!B4 -> 20
A17: 8 | B17: Quản lý danh mục sản phẩm | C17: Danh sách danh mục sản phẩm | D17: ='Danh sách danh mục sản phẩm'!B4 -> 12
C18: Thêm danh mục sản phẩm | D18: ='Thêm danh mục sản phẩm'!B4 -> 10
C19: Chỉnh sửa danh mục sản phẩm | D19: ='Cập nhật danh mục sản phẩm'!B4 -> 11
A20: 9 | B20: Quản lý sản phẩm | C20: Danh sách sản phẩm | D20: ='Danh sách sản phẩm'!B4 -> 16
C21: Thêm sản phẩm | D21: ='Thêm sản phẩm'!B4 -> 25
C22: Chỉnh sửa sản phẩm | D22: ='Cập nhật sản phẩm'!B4 -> 25
A23: 10 | B23: Bài viết | C23: Bài viết | D23: ='Bài viết'!B4 -> 15
A24: 11 | B24: Quản lý công thức | C24: Danh sách công thức | D24: ='Danh sách công thức'!B4 -> 18
C25: Thêm công thức | D25: ='Thêm công thức'!B4 -> 20
C26: Chỉnh sửa công thức | D26: ='Chỉnh sửa công thức'!B4 -> 17
C27: Tổng: | D27: =SUM(D5:D26) -> 350

Sheet Báo cáo kiểm tra
A1: Báo cáo thử nghiệm
A3: Tên dự án | B3: Website bán thời trang | E3: Creator | H3: Phạm Nguyễn Đình huy
E4: Người đánh giá/phê duyệt | H4: Cả nhóm
E5: Ngày triển khai | H5: 44114
A6: Ghi chú | B6: Tính năng đang chờ xử lý :
C7: Hoàn thành | E7: Lỗi | G7: Chưa Kiểm tra | I7: Bị chặn | K7: Số trường hợp thử nghiệm | M7: % Thành công | O7: % Coverage
A9: STT | B9: Tên hiển thị | C9: Vòng 1 | D9: Vòng 2 | E9: Vòng 1 | F9: Vòng 2 | G9: Vòng 1 | H9: Vòng 2 | I9: Vòng 1 | J9: Vòng 2 | K9: Vòng 1 | L9: Vòng 2 | M9: Vòng 1 | N9: Vòng 2 | O9: Vòng 1 | P9: Vòng 2
A10: 1 | B10: Đăng nhập | C10: 15 | D10: 15 | E10: 0 | F10: #REF! | G10: #REF! | H10: #REF! | I10: #REF! | J10: #REF! | K10: 15 | L10: 15 | M10: =ROUND(C10*100/K10,1) -> 100 | N10: =ROUND(D10*100/L10,1) -> 100 | O10: =ROUND((C10+E10)*100/K10,1) -> 100 | P10: =ROUND((D10+F10)*100/L10,1) -> #VALUE!
A11: 2 | B11: Quản lý sản phẩm
A12: 3 | B12: Quản lý danh mục | C12: 12 | D12: 12 | E12: 0 | F12: #REF! | G12: #REF! | H12: #REF! | I12: #REF! | J12: #REF! | K12: 12 | L12: 12 | M12: =ROUND(C12*100/K12,1) -> 100 | N12: =ROUND(D12*100/L12,1) -> 100 | O12: =ROUND((C12+E12)*100/K12,1) -> 100 | P12: =ROUND((D12+F12)*100/L12,1) -> #VALUE!
A13: 4 | B13: Quản lý nhãn hiệu
A14: 5 | B14: Quản lý mã khuyến mãi | C14: 8 | D14: 8 | E14: =#REF! -> #REF! | F14: =#REF! -> #REF! | G14: =#REF! -> #REF! | H14: =#REF! -> #REF! | I14: =#REF! -> #REF! | J14: =#REF! -> #REF! | K14: 4 | L14: 4 | M14: =ROUND(C14*100/K14,1) -> 200 | N14: =ROUND(D14*100/L14,1) -> 200 | O14: =ROUND((C14+E14)*100/K14,1) -> #REF! | P14: =ROUND((D14+F14)*100/L14,1) -> #REF!
A15: 6 | B15: Quản lý hóa đơn
A16: 7 | B16: Quản lý tài khoản người dùng | C16: 15 | D16: 15 | E16: 0 | F16: 0 | G16: 0 | H16: 0 | I16: 0 | J16: 0 | K16: 15 | L16: 15 | M16: =ROUND(C16*100/K16,1) -> 100 | N16: 100 | O16: 100 | P16: 100
A17: 8 | B17: Quản lý công thức | C17: 20 | D17: 20 | E17: =#REF! -> #REF! | F17: =#REF! -> #REF! | G17: =#REF! -> #REF! | H17: =#REF! -> #REF! | I17: =#REF! -> #REF! | J17: =#REF! -> #REF! | K17: 20 | L17: 20 | M17: =ROUND(C17*100/K17,1) -> 100 | N17: =ROUND(D17*100/L17,1) -> 100 | O17: =ROUND((C17+E17)*100/K17,1) -> #REF! | P17: =ROUND((D17+F17)*100/L17,1) -> #REF!
A18: 9 | B18: Quản lý bình luận | C18: 27 | D18: 27 | E18: =#REF! -> #REF! | F18: 0 | G18: =#REF! -> #REF! | H18: =#REF! -> #REF! | I18: =#REF! -> #REF! | J18: 0 | K18: 27 | L18: 27 | M18: =ROUND(C18*100/K18,1) -> 100 | N18: =ROUND(D18*100/L18,1) -> 100 | O18: =ROUND((C18+E18)*100/K18,1) -> #REF! | P18: =ROUND((D18+F18)*100/L18,1) -> 100
A19: 10 | B19: Tìm kiếm | C19: 17 | D19: 17 | E19: 0 | F19: =#REF! -> #REF! | G19: 0 | H19: 0 | I19: 0 | J19: =#REF! -> #REF! | K19: 17 | L19: 17 | M19: =ROUND(C19*100/K19,1) -> 100 | N19: =ROUND(D19*100/L19,1) -> 100 | O19: =ROUND((C19+E19)*100/K19,1) -> 100 | P19: =ROUND((D19+F19)*100/L19,1) -> #REF!
A20: 11 | B20: Quản lý thống kê | C20: 18 | D20: 18 | E20: =#REF! -> #REF! | F20: 0 | G20: =#REF! -> #REF! | H20: =#REF! -> #REF! | I20: =#REF! -> #REF! | J20: 0 | K20: 18 | L20: 18 | M20: =ROUND(C20*100/K20,1) -> 100 | N20: =ROUND(D20*100/L20,1) -> 100 | O20: =ROUND((C20+E20)*100/K20,1) -> #REF! | P20: =ROUND((D20+F20)*100/L20,1) -> 100
B21: Sub total | C21: =SUM(C10:C20) -> 132 | D21: =SUM(D10:D20) -> 132 | E21: =SUM(E10:E20) -> #REF! | F21: =SUM(F10:F20) -> #REF! | G21: =SUM(G10:G20) -> #REF! | H21: =SUM(H10:H20) -> #REF! | I21: =SUM(I10:I20) -> #REF! | J21: =SUM(J10:J20) -> #REF! | ... P21: =SUM(P10:P20) -> #VALUE!
C22: Vòng 1 | D22: Vòng2
B23: Kiểm tra phủ sóng | C23: =ROUND((C21+E21)*100/K21,1) -> #REF! | D23: =ROUND((D21+F21)*100/L21,1) -> #REF! | E23: %
B24: Kiểm tra thành công phủ sống | C24: =ROUND(C21*100/K21,1) -> 103.1 | D24: =ROUND(D21*100/L21,1) -> 103.1 | E24: %

Sheet Đăng nhập
A1: Project Name | B1: CoffeeGo-Nền tảng đặt bàn quán cà phê tích hợp AI Assistant và thanh toán điện tử
A2: Module Code | B2: Đăng nhập
B3: Hoàn thành | C3: Lỗi | D3: Chưa kiểm tra | E3: Bị chăn | F3: Tổng số trường hợp thử nghiệm
A4: Round 1 | B4: =COUNTA(A11:A30)- 1 -> 19 | C4: =COUNTIF(G:G,"Failed") -> 0 | D4: =COUNTIF(G:G,"Untested") -> 0 | E4: =COUNTIF(G:G,"Blocked") -> 0 | F4: =B4 -> 19
A5: Round 2 | B5: =COUNTA(A22:A30) -> 9 | C5: =COUNTIF(J:J,"Failed") -> 0 | D5: =COUNTIF(J:J,"Untested") -> 0 | E5: =COUNTIF(J:J,"Blocked") -> 0 | F5: =B5 -> 9
A7: Test Case ID | B7: Mô tả | C7: Hành động | D7: Điều kiện tiên quyết | E7: Kết quả mong đợi | F7: Kết quả thực tế | G7: Kết quả | J7: Kết quả | M7: Chú thích
G8: Vòng 1 | J8: Vòng 2
G9: Trạng thái | H9: Ngày kiểm tra | I9: Người kiểm tra | J9: Trạng thái | K9: Ngày kiểm tra | L9: Người kiểm tra
A10: GUI_SHOW Trang đăng nhập
A11: GUI-DN01 | B11: [ Đăng nhập tài khoản] Label | E11: -Label : black -Status : enable | F11: -Label : black -Status : enable | G11: Passed | H11: 45955 | I11: Huy
A12: GUI-DN02 | B12: [Bạn có chưa có tài khoản]Label | E12: -Label : black -Status : enable | F12: -Label : black -Status : enable | G12: Passed | H12: 45955 | I12: Huy
A13: GUI-DN03 | B13: [Đăng ký tại đây]Link | E13: -Label : red -Status : enable | F13: -Label : red -Status : enable | G13: Passed | H13: 45955 | I13: Huy
A14: GUI-DN04 | B14: [Email] Label | E14: -Text color : black -Status : enable | F14: -Label : black -Status : enable | G14: Passed | H14: 45955 | I14: Huy
A15: GUI-DN05 | B15: [Nhập email của bạn] Textbox | E15: -Label : black -Status : enable | F15: -Label : black -Status : enable | G15: Passed | H15: 45955 | I15: Huy
A16: GUI-DN06 | B16: [Mật khẩu] Label | E16: -Label : black -Status : enable | F16: -Label : black -Status : enable | G16: Passed | H16: 45955 | I16: Huy
A17: GUI-DN07 | B17: [Nhập mật khẩu] Textbox | E17: -Label : black -Status : enable | F17: -Label : black -Status : enable | G17: Passed | H17: 45955 | I17: Huy
A18: GUI-DN08 | B18: [Mật khẩu] Textbox | E18: -Text color : black -Status : enable | F18: -Text color : black -Status : enable | G18: Passed | H18: 45955 | I18: Huy
A19: GUI-DN09 | B19: [Quên mất khẩu]Link | E19: -Text color :red -Status : enable | F19: -Text color :red -Status : enable | G19: Passed | H19: 45955 | I19: Huy
A20: GUI-DN10 | B20: [Đăng nhập] Button | E20: -Text color : white - Background color : red -Status : enable | F20: -Text color : white - Background color : red -Status : enable | G20: Passed | H20: 45955 | I20: Huy
A21: FUNCTION_SHOW Trang đăng nhập
A22: FUNC-DN01 | B22: Đăng nhập thành công vào trang admin | C22: 1. Nhập email và Mật khẩu của admin 2. Click "Đăng nhập". | D22: Truy cập vào hệ thống | E22: Đi đến trang quản lý | F22: Đi đến trang quản lý | G22: Passed | H22: 45955 | I22: Huy | J22: Passed | K22: 45959 | L22: Huy
A23: FUNC-DN02 | B23: Đăng nhập thất bại khi điền sai"'Email" | C23: 1. Nhập Email sai 2. Click "Đăng nhập". | D23: Truy cập vào hệ thống | E23: Hệ thống thông báo lỗi : "Sai email hoặc mật khẩu!" | F23: Hệ thống thông báo lỗi : "Sai email hoặc mật khẩu!" | G23: Passed | H23: 45955 | I23: Huy | J23: Passed | K23: 45959 | L23: Huy
A24: FUNC-DN03 | B24: Đăng nhập thất bại khi điền sai "Mật khẩu " | C24: 1. Nhập Mật khẩu sai 2. Click "Đăng nhập". | D24: Truy cập vào hệ thống | E24: Hệ thống thông báo lỗi : "Sai email hoặc mật khẩu!" | F24: Hệ thống thông báo lỗi : "Sai email hoặc mật khẩu!" | G24: Passed | H24: 45955 | I24: Huy | J24: Passed | K24: 45959 | L24: Huy
A25: FUNC-DN04 | B25: Đăng nhập thất bại khi điền sai "Email" và "Mật khẩu" | C25: 1.Nhập sai Email 2.Nhập sai Mật khẩu 3.Click "Đăng nhập" | D25: Truy cập vào hệ thống | E25: Hệ thống thông báo lỗi :"Sai email hoặc mật khẩu" | F25: Hệ thống thông báo lỗi :"Sai email hoặc mật khẩu" | G25: Passed | H25: 45955 | I25: Huy | J25: Passed | K25: 45959 | L25: Huy
A26: FUNC-DN05 | B26: Để trống trường "Mật khẩu". | C26: 1 .Nhập tên tài khoản 2. Không nhập dữ liệu trường "Mật khẩu". 3. Click "Đăng nhập". | D26: Truy cập vào hệ thống | E26: Thông báo lỗi : "Vui lòng nhập mật khẩu " | F26: Thông báo lỗi : "Vui lòng nhập mật khẩu " | G26: Passed | H26: 45955 | I26: Huy | J26: Passed | K26: 45959 | L26: Huy
A27: FUNC-DN06 | B27: Để trống trường "email" | C27: 1 .Không nhập dữ liệu trường "Email". 2. Nhập mật khẩu 3. Click "Đăng nhập". | D27: Truy cập vào hệ thống | E27: Hệ thống thông báo lỗi : "Vui lòng nhập email". | F27: Hệ thống thông báo lỗi : "Vui lòng nhập email". | G27: Passed | H27: 45955 | I27: Huy | J27: Passed | K27: 45959 | L27: Huy
A28: FUNC-DN07 | B28: Để trống tất cả các trường dữ liêu | C28: 1 .Không nhập email 2. Không nhập dữ liệu trường "Mật khẩu". 3. Click "Đăng nhập". | D28: Truy cập vào hệ thống | E28: Hệ thống thông báo :" Vui lòng nhập email ", "Vui lòng nhập mật khẩu" | F28: Hệ thống thông báo :" Vui lòng nhập email ", "Vui lòng nhập mật khẩu" | G28: Passed | H28: 45955 | I28: Huy | J28: Passed | K28: 45959 | L28: Huy
A29: FUNC-DN08 | B29: Click "Đăng ký tại đây" | C29: 1. Click "Đăng ký tại đây" | D29: Truy cập vào hệ thống | E29: Chuyển sang trang đăng ký | F29: Chuyển sang trang đăng ký | G29: Passed | H29: 45955 | I29: Huy | J29: Passed | K29: 45959 | L29: Huy
A30: FUNC-DN09 | B30: Click "Quên mật khẩu" | C30: 1. Click "Quên mật khẩu" | D30: Truy cập vào hệ thống | E30: Chuyển sang trang quên mật khẩu | F30: Chuyển sang trang quên mật khẩu | G30: Passed | H30: 45955 | I30: Huy | J30: Passed | K30: 45959 | L30: Huy

Sheet Đăng ký 
A1: Project Name | B1: CoffeeGo-Nền tảng đặt bàn quán cà phê tích hợp AI Assistant và thanh toán điện tử
A2: Module Code | B2: Đăng ký
B3: Hoàn thành | C3: Lỗi | D3: Chưa kiểm tra | E3: Bị chăn | F3: Tổng số trường hợp thử nghiệm
A4: Round 1 | B4: =COUNTA(A11:A30)- 1 -> 19 | C4: =COUNTIF(G:G,"Failed") -> 3 | D4: =COUNTIF(G:G,"Untested") -> 0 | E4: =COUNTIF(G:G,"Blocked") -> 0 | F4: =B4 -> 19
A5: Round 2 | B5: =COUNTA(A23:A30) -> 8 | C5: =COUNTIF(J:J,"Failed") -> 1 | D5: =COUNTIF(J:J,"Untested") -> 0 | E5: =COUNTIF(J:J,"Blocked") -> 0 | F5: =B5 -> 8
A7: Test Case ID | B7: Mô tả | C7: Quy trình | D7: Điều kiện tiên quyết | E7: Kết quả mong đợi | F7: Kết quả thực tế | G7: Kết quả | J7: Kết quả | M7: Chú thích
G8: Vòng 1 | J8: Vòng 2
G9: Trạng thái | H9: Ngày kiểm tra | I9: Người kiểm tra | J9: Trạng thái | K9: Ngày kiểm tra | L9: Người kiểm tra
A10: GUI_SHOW Đăng ký
A11: GUI-DK01 | B11: [Đăng ký tài khỏan] Label | E11: -Label : black -Status : enable | F11: -Label : black -Status : enable | G11: Passed | H11: 45955 | I11: Khánh
A12: GUI-DK02 | B12: [Bạn đã có tài khoản]Label | E12: -Label : black -Status : enable | F12: -Label : black -Status : enable | G12: Passed | H12: 45955 | I12: Khánh
A13: GUI-DK03 | B13: [Đăng nhập tại đây]Link | E13: -Label : red -Status : enable | F13: -Label : red -Status : enable | G13: Passed | H13: 45955 | I13: Khánh
A14: GUI-DK04 | B14: [Thông tin cá nhân] Label | E14: -Label : black -Status : enable | F14: -Label : black -Status : enable | G14: Passed | H14: 45955 | I14: Khánh
A15: GUI-DK05 | B15: [Name] Label | E15: -Label : black -Status : enable | F15: -Label : black -Status : enable | G15: Passed | H15: 45955 | I15: Khánh
A16: GUI-DK06 | B16: [Nhập tên của bạn]Textbox | E16: -Label : black -Status : enable | F16: -Label : black -Status : enable | G16: Passed | H16: 45955 | I16: Khánh
A17: GUI-DK07 | B17: [Email] Label | E17: -Label : black -Status : enable | F17: -Label : black -Status : enable | G17: Passed | H17: 45955 | I17: Khánh
A18: GUI-DK08 | B18: [Nhập email của bạn]Textbox | E18: -Label : black -Status : enable | F18: -Label : black -Status : enable | G18: Passed | H18: 45955 | I18: Khánh
A19: GUI-DK09 | B19: [Mật khẩu] Label | E19: -Label : black -Status : enable | F19: -Label : black -Status : enable | G19: Passed | H19: 45955 | I19: Khánh
A20: GUI-DK10 | B20: [Nhập mật khẩu] Textbox | E20: -Label : black -Status : enable | F20: -Label : black -Status : enable | G20: Passed | H20: 45955 | I20: Khánh
A21: GUI-DK11 | B21: [Đăng ký] Button | E21: -Text color : white - Background color : red -Status : enable | F21: -Text color : white - Background color : red -Status : enable | G21: Passed | H21: 45955 | I21: Khánh
A22: FUNCTION_SHOW Đăng ký
A23: FUNC-DK01 | B23: Đăng ký với đầy đủ thông tin | C23: 1.Điền tất cả đầy đủ thông tin 2.Click: "Đăng ký " | D23: Truy cập hệ thống | E23: Hệ thống sẽ thông báo "Đăng ký thành công " | F23: Hệ thống sẽ thông báo "Đăng ký thành công " | G23: Passed | H23: 45955 | I23: Khánh | J23: Passed | K23: 45959 | L23: Khánh
A24: FUNC-DK02 | B24: Đăng ký thất bại khi thiếu "Name" | C24: 1.Điền thông tin 2.Để trống "Email" 3.Click "Đăng ký" | D24: Truy cập hệ thống | E24: Hệ thống sẽ thông báo "Vui lòng nhập tên " | F24: Hệ thống sẽ thông báo "Vui lòng nhập tên " | G24: Passed | H24: 45955 | I24: Khánh | J24: Passed | K24: 45959 | L24: Khánh
A25: FUNC-DK03 | B25: Đăng ký thất bại khi thiếu "Email" | C25: 1.Điền thông tin 2.Để trống "Email" 3.Click "Đăng ký" | D25: Truy cập hệ thống | E25: Hệ thống sẽ thông báo "Vui lòng nhập email " | F25: Hệ thống sẽ thông báo "Vui lòng nhập email " | G25: Passed | H25: 45955 | I25: Khánh | J25: Passed | K25: 45959 | L25: Khánh
A26: FUNC-DK04 | B26: Đăng ký thất bại khi thiếu "Mật khẩu" | C26: 1.Điền thông tin 2.Để trống "Mật khẩu " 3.Click "Đăng ký" | D26: Truy cập hệ thống | E26: Hệ thống sẽ thông báo "Vui lòng nhập Mật khẩu " | F26: Hệ thống sẽ thông báo "Vui lòng nhập Mật khẩu " | G26: Passed | H26: 45955 | I26: Khánh | J26: Passed | K26: 45959 | L26: Khánh
A27: FUNC-DK05 | B27: Đăng ký thất bại khi "Email" tồn tại | C27: 1.Điền Email đã tồn tại 2.Click "Đăng ký " | D27: Truy cập hệ thống | E27: Hệ thống sẽ thông báo lỗi "Email đã được sử dụng " | F27: Hệ thống không thông báo "Đăng ký thành công " | G27: Failed | H27: 45955 | I27: Khánh | J27: Passed | K27: 45959 | L27: Khánh
A28: FUNC-DK06 | B28: Đăng ký thành công khi "Mật khẩu " đầy đủ các ký tự (abc&0-9&ký tự đặc biệt) | C28: 1.Điền các thông tin 2.Click "Đăng ký " | D28: Truy cập hệ thống | E28: Hệ thống sẽ thông báo "Đăng ký thành công " | F28: Hệ thống sẽ thông báo "Đăng ký thành công " | G28: Passed | H28: 45955 | I28: Khánh | J28: Passed | K28: 45959 | L28: Khánh
A29: FUNC-DK07 | B29: Đăng ký thất bại khi nhập mật khẩu không đủ 8 ký tự | C29: 1.Điền các thông tin 2.Click "Đăng ký " | D29: Truy cập hệ thống | E29: Hệ thống sẽ thông báo "Mật khẩu phải có ít nhất 8 ký tự". | F29: Hệ thống không thông báo "Mật khẩu phải có ít nhất 8 ký tự". | G29: Failed | H29: 45955 | I29: Khánh | J29: Passed | K29: 45959 | L29: Khánh
A30: FUNC-DK08 | B30: Đăng ký thất bại khi nhập mật khẩu chỉ có số/chữ/ký tự đặc biệt | C30: 1.Điền các thông tin 2.Click "Đăng ký " | D30: Truy cập hệ thống | E30: Hệ thống sẽ thông báo "Mật khẩu phải bao gồm cả số, chữ cái và ký tự đặc biệt". | F30: Hệ thống không thông báo "Mật khẩu phải bao gồm cả số, chữ cái và ký tự đặc biệt". | G30: Failed | H30: 45955 | I30: Khánh | J30: Failed | K30: 45959 | L30: Khánh

Sheet Danh sách sản phẩm 
A1: Project Name | B1: XÂY DỰNG HỆ THỐNG QUẢN LÝ VÀ KIỂM DUYỆT VĂN BẢN TÍCH HỢP CHỮ KÝ SỐ VỚI THUẬT TOÁN RSA
A2: Module Code | B2: Đổi mật khẩu
B3: Hoàn thành | C3: Lỗi | D3: Chưa kiểm tra | E3: Bị chăn | F3: Tổng số trường hợp thử nghiệm
A4: Round 1 | B4: 15 | C4: 0 | D4: =COUNTIF(G11:G25,"Untested") -> 0 | E4: =COUNTIF(G11:G25,"Blocked") -> 0 | F4: =B4 -> 15
A5: Round 2 | B5: 8 | C5: 0 | D5: =COUNTIF(J11:J25,"Untested") -> 0 | E5: =COUNTIF(J11:J25,"Blocked") -> 0 | F5: =B5 -> 8
A7: Test Case ID | B7: Mô tả | C7: Quy trình | D7: Điều kiện tiên quyết | E7: Kết quả mong đợi | F7: Kết quả thực tế | G7: Kết quả | J7: Kết quả | M7: Chú thích
G8: Vòng 1 | J8: Vòng 2
G9: Trạng thái | H9: Ngày kiểm tra | I9: Người kiểm tra | J9: Trạng thái | K9: Ngày kiểm tra | L9: Người kiểm tra
A10: GUI_SHOW Đăng ký
A11: GUI-DK01 | B11: [Trang đăng ký!] Lable | E11: -Label : black -Status : enable | F11: -Label : black -Status : enable | G11: Passed | H11: 45590 | I11: Lộc
A12: GUI-DK02 | B12: [Tên đăng nhập]textbox | E12: -Label : black -Status : enable | F12: -Label : black -Status : enable | G12: Passed | H12: 45590 | I12: Lộc
A13: GUI-DK03 | B13: [Email ] Textbox | E13: -Text color : black -Status : enable | F13: -Text color : black -Status : enable | G13: Passed | H13: 45590 | I13: Lộc
A14: GUI-DK04 | B14: [Số điện thoại] Textbox | E14: -Text color : black -Status : enable | F14: -Text color : black -Status : enable | G14: Passed | H14: 45590 | I14: Lộc
A15: GUI-DK05 | B15: [Mật khẩu]Textbox | E15: -Text color : black -Status : enable | F15: -Text color : black -Status : enable | G15: Passed | H15: 45590 | I15: Lộc
A16: GUI-DK06 | B16: [Đăng ký] Button | E16: -Text color : white - Background color : yellow -Status : enable | F16: -Text color : white - Background color : yellow -Status : enable | G16: Passed | H16: 45590 | I16: Lộc
A17: FUNCTION_SHOW Đăng ký
A18: FUNC-DK01 | B18: Đăng ký với đầy đủ thông tin | C18: 1.Điền tất cả đầy đủ thông tin 2.Click: "Đăng ký " | D18: Truy cập hệ thống | E18: Hệ thống sẽ thông báo "Đăng ký thành công " | F18: Hệ thống sẽ thông báo "Đăng ký thành công " | G18: Passed | H18: 45592 | I18: Dũng | J18: Passed | K18: 45592
A19: FUNC-DK02 | B19: Đăng ký thất bại khi thiếu "Tên đăng nhập" | C19: 1.Điền thông tin 2.Để trống "Tên đăng nhập" 3.Click "Đăng ký" | D19: Truy cập hệ thống | E19: Hệ thống sẽ thông báo "Vui lòng nhập tên đăng nhập " | F19: Hệ thống sẽ thông báo "Vui lòng nhập tên đăng nhập " | G19: Passed | I19: Dũng
A20: FUNC-DK03 | B20: Đăng ký thất bại khi thiếu "Email" | C20: 1.Điền thông tin 2.Để trống "Email" 3.Click "Đăng ký" | D20: Truy cập hệ thống | E20: Hệ thống sẽ thông báo "Vui lòng nhập Email " | F20: Hệ thống sẽ thông báo "Vui lòng nhập Email " | G20: Passed | I20: Dũng
A21: FUNC-DK04 | B21: Đăng ký thất bại khi thiếu "Số điện thoại" | C21: 1.Điền thông tin 2.Để trống "Số điện thoạil" 3.Click "Đăng ký" | D21: Truy cập hệ thống | E21: Hệ thống sẽ thông báo "Vui lòng nhập Số điện thoại " | F21: Hệ thống sẽ thông báo "Vui lòng nhập Số điện thoại " | G21: Passed
A22: FUNC-DK05 | B22: Đăng ký thất bại khi thiếu "Mật khẩu" | C22: 1.Điền thông tin 2.Để trống "Mật khẩu " 3.Click "Đăng ký" | D22: Truy cập hệ thống | E22: Hệ thống sẽ thông báo "Vui lòng nhập Mật khẩu " | F22: Hệ thống sẽ thông báo "Vui lòng nhập Mật khẩu " | G22: Passed
A23: FUNC-DK06 | B23: Đăng ký thất bại khi "Tên đăng nhập" tồn tại | C23: 1.Điền Tên đăng nhập đã tồn tại 2.Click: "Đăng ký " | D23: Truy cập hệ thống | E23: Hệ thống sẽ thông báo lỗi "Tên người dùng đã được sử dụng " | F23: Hệ thống sẽ thông báo lỗi "Tên người dùng đã được sử dụng " | G23: Passed | H23: 45592 | I23: Dũng | J23: Passed | K23: 45592
A24: FUNC-DK07 | B24: Đăng ký thất bại khi "Email" tồn tại | C24: 1.Điền Email đã tồn tại 2.Click "Đăng ký " | D24: Truy cập hệ thống | E24: Hệ thống sẽ thông báo lỗi "Email đã được sử dụng " | F24: Hệ thống sẽ thông báo "Đăng ký thành công " | G24: Failed | H24: 45592 | I24: Dũng | J24: Passed | K24: 45592
A25: FUNC-DK08 | B25: Đăng ký thất bại khi "Số điện thoại " tồn tại | C25: 1.Điền Số điện thoại đã tồn tại 2.Click "Đăng ký " | D25: Truy cập hệ thống | E25: Hệ thống sẽ thông báo lỗi "Số điện thoại đã được sử dụng " | F25: Hệ thống sẽ thông báo "Đăng ký thành công " | G25: Failed | H25: 45592 | I25: Dũng | J25: Passed | K25: 45592
A26: FUNC-DK09 | B26: Đăng ký thành công khi "Mật khẩu " đầy đủ các ký tự (abc&0-9) | C26: 1.Điền các thông tin 2.Click "Đăng ký " | D26: Truy cập hệ thống | E26: Hệ thống sẽ thông báo "Đăng ký thành công " | F26: Hệ thống sẽ thông báo "Đăng ký thành công " | G26: Passed | H26: 45592 | I26: Dũng | J26: Passed | K26: 45592
A27: FUNC-DK10 | B27: Đăng ký thất bại khi nhập mật khẩu "abc" | C27: 1.Điền các thông tin 2.Click "Đăng ký " | D27: Truy cập hệ thống | E27: Hệ thống sẽ thông báo "Mật khẩu phải có ít nhất một chữ số ('0'-'9')". | F27: Hệ thống sẽ thông báo "Mật khẩu phải có ít nhất một chữ số ('0'-'9')". | G27: Passed | I27: Dũng
A28: FUNC-DK11 | B28: Đăng ký thất bại khi nhập mật khẩu "0-9" | C28: 1.Điền các thông tin 2.Click "Đăng ký " | D28: Truy cập hệ thống | E28: Hệ thống sẽ thông báo "Mật khẩu phải có ít nhất một chữ số ('0'-'9')". | F28: Hệ thống sẽ thông báo "Mật khẩu phải có ít nhất một chữ số ('0'-'9')". | G28: Passed

Sheet Quên mật khẩu
A1: Project Name | B1: CoffeeGo-Nền tảng đặt bàn quán cà phê tích hợp AI Assistant và thanh toán điện tử
A2: Module Code | B2: Quên mật khẩu
B3: Hoàn thành | C3: Lỗi | D3: Chưa kiểm tra | E3: Bị chặn | F3: Tổng lần kiểm tra
A4: Round 1 | B4: =COUNTA(A35:A48)- 1 -> 13 | C4: =COUNTIF(G:G,"Failed") -> 0 | D4: =COUNTIF(G:G,"Untested") -> 0 | E4: =COUNTIF(G:G,"Blocked") -> 0 | F4: =B4 -> 13
A5: Round 2 | B5: =COUNTA(A43:A48) -> 6 | C5: =COUNTIF(J:J,"Failed") -> 0 | D5: =COUNTIF(J:J,"Untested") -> 0 | E5: =COUNTIF(J:J,"Blocked") -> 0 | F5: =B5 -> 6
A31: Test Case ID | B31: Mô tả | C31: Quy trình | D31: Điều kiện tiên quyết | E31: Kết quả mong đợi | F31: Kết quả thực tế | G31: Kết quả | M31: Chú thích
G32: Vòng 1 | J32: Vòng 2
G33: Trạng thái | H33: Ngày kiểm tra | I33: Người kiểm tra | J33: Trạng thái | K33: Ngày kiểm tra | L33: Người kiểm tra
A34: GUI_SHOW Quên mật khẩu
A35: GUI-QMK01 | B35: [Quên mật khẩu] Label | E35: -Label : black -Status : enable | F35: -Label : black -Status : enable | G35: Passed | H35: 45955 | I35: Tấn
A36: GUI-QMK02 | B36: [Bạn có chưa có tài khoản] Label | E36: -Label :black -Status : enable | F36: -Label :black -Status : enable | G36: Passed | H36: 45955 | I36: Tấn
A37: GUI-QMK03 | B37: [Đăng ký tại đây]Link | E37: -Label :red -Status : enable | F37: -Label :red -Status : enable | G37: Passed | H37: 45955 | I37: Tấn
A38: GUI-QMK04 | B38: [Email] Label | E38: -Label : black -Status : enable | F38: -Label : black -Status : enable | G38: Passed | H38: 45955 | I38: Tấn
A39: GUI-QMK05 | B39: [Nhập email của bạn] Textbox | E39: -Label : black -Status : enable | F39: -Label : black -Status : enable | G39: Passed | H39: 45955 | I39: Tấn
A40: GUI-QMK06 | B40: [Lấy lại mật khẩu] Button | E40: -Text color : black -Background color: red -Status : enable | F40: -Text color : black -Background color: red -Status : enable | G40: Passed | H40: 45955 | I40: Tấn
A41: GUI-QMK07 | B41: [Quay lại] Link | E41: -Label : white -Status : enable | F41: -Label : white -Status : enable | G41: Passed | H41: 45955 | I41: Tấn
A42: FUNCTION_SHOW Quên mật khẩu
A43: FUNC-QMK01 | B43: Lấy lại mật khẩu thành công | C43: 1.Nhập email của khách hàng 2.Click"Lấy lại mật khẩu" 3.Gửi link đổi mật khẩu 4.Nhập mật khẩu mới 5.Click đặt lại mật khẩu | D43: Truy cập hệ thống | E43: Hệ thống thông báo đặt mật khẩu thành công và chuyển sang trang đăng nhập | F43: Hệ thống thông báo đặt mật khẩu thành công và chuyển sang trang đăng nhập | G43: Passed | H43: 45955 | I43: Tấn | J43: Passed | K43: 45959 | L43: Tấn
A44: FUNC-QMK02 | B44: Lấy lại mật khẩu không thành công khi điền sai email | C44: 1.Nhập sai email 2.Click"Lấy lại mật khẩu" | D44: Truy cập hệ thống | E44: Hệ thống thông báo lỗi : "email không tồn tại!" | F44: Hệ thống thông báo lỗi : "email không tồn tại!" | G44: Passed | H44: 45955 | I44: Tấn | J44: Passed | K44: 45959 | L44: Tấn
A45: FUNC-QMK03 | B45: Lấy lại mật khẩu không thành công khi không điền email | C45: 1.Để trống"Email" 2.Click"Lấy lại mật khẩu" | D45: Truy cập hệ thống | E45: Hệ thống sẽ thông báo "Vui lòng nhập email!" | F45: Hệ thống sẽ thông báo "Vui lòng nhập email!" | G45: Passed | H45: 45955 | I45: Tấn | J45: Passed | K45: 45959 | L45: Tấn
A46: FUNC-QMK04 | B46: Lấy lại mật khẩu không thành công khi không đúng định dang email | C46: 1.Nhập thiếu ký tự"@" 2.Click"Lấy lại mật khẩu" | D46: Truy cập hệ thống | E46: Hệ thống sẽ thông báo "Lỗi định dang email" | F46: Hệ thống sẽ thông báo "Lỗi định dang email" | G46: Passed | H46: 45955 | I46: Tấn | J46: Passed | K46: 45959 | L46: Tấn
A47: FUNC-QMK05 | B47: Click "Đăng ký tại đây" | C47: 1. Click "Đăng ký tại đây" | D47: Truy cập vào hệ thống | E47: Chuyển sang trang đăng ký | F47: Chuyển sang trang đăng ký | G47: Passed | H47: 45955 | I47: Tấn | J47: Passed | K47: 45959 | L47: Tấn
A48: FUNC-QMK06 | B48: Click "Quay lại" | C48: 1. Click"Quay lại" | D48: Truy cập hệ thống | E48: Quay lại trang đăng nhập | F48: Quay lại trang đăng nhập | G48: Passed | H48: 45955 | I48: Tấn | J48: Passed | K48: 45959 | L48: Tấn

Sheet Đổi mật khẩu
A1: Project Name | B1: CoffeeGo-Nền tảng đặt bàn quán cà phê tích hợp AI Assistant và thanh toán điện tử
A2: Module Code | B2: Đổi mật khẩu
B3: Hoàn thành | C3: Lỗi | D3: Chưa kiểm tra | E3: Bị chặn | F3: Tổng lần kiểm tra
A4: Round 1 | B4: =COUNTA(A35:A52)- 1 -> 17 | C4: =COUNTIF(G:G,"Failed") -> 1 | D4: =COUNTIF(G:G,"Untested") -> 0 | E4: =COUNTIF(G:G,"Blocked") -> 0 | F4: =B4 -> 17
A5: Round 2 | B5: =COUNTA(A47:A52) -> 6 | C5: =COUNTIF(J:J,"Failed") -> 0 | D5: =COUNTIF(J:J,"Untested") -> 0 | E5: =COUNTIF(J:J,"Blocked") -> 0 | F5: =B5 -> 6
A31: Test Case ID | B31: Mô tả | C31: Quy trình | D31: Điều kiện tiên quyết | E31: Kết quả mong đợi | F31: Kết quả thực tế | G31: Kết quả | M31: Chú thích
G32: Vòng 1 | J32: Vòng 2
G33: Trạng thái | H33: Ngày kiểm tra | I33: Người kiểm tra | J33: Trạng thái | K33: Ngày kiểm tra | L33: Người kiểm tra
A34: GUI_SHOW Đổi mật khẩu
A35: GUI - ĐMK01 | B35: [Trang tài khoản] Label | E35: - Text: Black - Status: Enable | F35: - Text: Black - Status: Enable | G35: Passed | H35: 45955 | I35: Đức
A36: GUI - ĐMK02 | B36: [Thông tin cá nhân] Label | E36: - Text: Black - Status: Enable | F36: - Text: Black - Status: Enable | G36: Passed | H36: 45955 | I36: Đức
A37: GUI - ĐMK03 | B37: [Lịch sử đơn hàng] Label | E37: - Text: Black - Status: Enable | F37: - Text: Black - Status: Enable | G37: Passed | H37: 45955 | I37: Đức
A38: GUI - ĐMK04 | B38: [Đổi mật khẩu] Label | E38: -Text color : white -Status : Enable -Background-color : green | F38: -Text color : white -Status : Enable -Background-color : green | G38: Passed | H38: 45955 | I38: Đức
A39: GUI - ĐMK05 | B39: [Mật khẩu cũ] Label | E39: - Text: Black - Status: Enable | F39: - Text: Black - Status: Enable | G39: Passed | H39: 45955 | I39: Đức
A40: GUI - ĐMK06 | B40: [Nhập mật khẩu] Label | E40: - Text: Black - Status: Enable | F40: - Text: Black - Status: Enable | G40: Passed | H40: 45955 | I40: Đức
A41: GUI - ĐMK07 | B41: [Mật khẩu mới] Label | E41: - Text: Black - Status: Enable | F41: - Text: Black - Status: Enable | G41: Passed | H41: 45955 | I41: Đức
A42: GUI - ĐMK08 | B42: [Nhập mật khẩu] Label | E42: - Text: Black - Status: Enable | F42: - Text: Black - Status: Enable | G42: Passed | H42: 45955 | I42: Đức
A43: GUI - ĐMK09 | B43: [Xác nhận mật khẩu mới] Label | E43: - Text: Black - Status: Enable | F43: - Text: Black - Status: Enable | G43: Passed | H43: 45955 | I43: Đức
A44: GUI - ĐMK10 | B44: [Nhập mật khẩu] Label | E44: - Text: Black - Status: Enable | F44: - Text: Black - Status: Enable | G44: Passed | H44: 45955 | I44: Đức
A45: GUI - ĐMK11 | B45: [Đặt lại mật khẩu] Button | E45: -Text color : white -Status : Enable -Background-color : blue | F45: -Text color : white -Status : Enable -Background-color : blue | G45: Passed | H45: 45955 | I45: Đức
A46: FUNCTION_SHOW Đổi mật khẩu
A47: FUNC-ĐMK01 | B47: Đổi mật khẩu thành công | C47: 1. Truy cập vào trang web 2. Nhập mật khẩu cũ 3.Nhập mật khẩu mới 4.Nhập xác nhận mật khẩu mới 5.Click "Đặt lại mật khẩu" | D47: Đăng nhập thành công vào hệ thống | E47: Hệ thống thông báo"Đặt lại mật khẩu thành công,đăng nhập lại" | F47: Hệ thống thông báo"Đặt lại mật khẩu thành công,đăng nhập lại" | G47: Passed | H47: 45955 | I47: Đức | J47: Passed | K47: 45959 | L47: Đức
A48: FUNC-ĐMK02 | B48: Đổi mật khẩu không thành công khi điền sai mật khẩu cũ | C48: 1. Truy cập vào trang web 2. Nhập mật khẩu cũ sai 3.Nhập mật khẩu mới 4.Nhập xác nhận mật khẩu mới 5.Click "Đặt lại mật khẩu" | D48: Đăng nhập thành công vào hệ thống | E48: Hệ thống thông báo"Mật khẩu cũ không đúng" | F48: Hệ thống thông báo"Mật khẩu cũ không đúng" | G48: Passed | H48: 45955 | I48: Đức | J48: Passed | K48: 45959 | L48: Đức
A49: FUNC-ĐMK03 | B49: Đổi mật khẩu không thành công khi điền thiếu mật khẩu cũ | C49: 1. Truy cập vào trang web 2. Không nhập mật khẩu cũ 3.Nhập mật khẩu mới 4.Nhập xác nhận mật khẩu mới 5.Click "Đặt lại mật khẩu" | D49: Đăng nhập thành công vào hệ thống | E49: Hệ thống thông báo"Vui lòng nhập đầy đủ thông tin" | F49: Hệ thống thông báo"Vui lòng nhập đầy đủ thông tin" | G49: Passed | H49: 45955 | I49: Đức | J49: Passed | K49: 45959 | L49: Đức
A50: FUNC-ĐMK04 | B50: Đổi mật khẩu không thành công khi điền thiếu mật khẩu mới | C50: 1. Truy cập vào trang web 2.Nhập mật khẩu cũ 3. Không nhập mật khẩu mới 4.Nhập xác nhận mật khẩu mới 5.Click "Đặt lại mật khẩu" | D50: Đăng nhập thành công vào hệ thống | E50: Hệ thống thông báo"Vui lòng nhập đầy đủ thông tin" | F50: Hệ thống không thông báo"Vui lòng nhập đầy đủ thông tin" | G50: Failed | H50: 45955 | I50: Đức | J50: Passed | K50: 45959 | L50: Đức
A51: FUNC-ĐMK05 | B51: Đổi mật khẩu không thành công khi điền thiếu xác nhận mật khẩu | C51: 1. Truy cập vào trang web 2. Nhập mật khẩu cũ 3.Nhập mật khẩu mới 4. Không nhập xác nhận mật khẩu mới 5.Click "Đặt lại mật khẩu" | D51: Đăng nhập thành công vào hệ thống | E51: Hệ thống thông báo"Vui lòng nhập đầy đủ thông tin" | F51: Hệ thống thông báo"Vui lòng nhập đầy đủ thông tin" | G51: Passed | H51: 45955 | I51: Đức | J51: Passed | K51: 45959 | L51: Đức
A52: FUNC-ĐMK06 | B52: Đổi mật khẩu không thành công khi điền xác nhận mật khẩu không khớp | C52: 1. Truy cập vào trang web 2.Nhập mật khẩu cũ 3.Nhập mật khẩu mới 4.Nhập xác nhận mật khẩu mới sai 5.Click "Đặt lại mật khẩu" | D52: Đăng nhập thành công vào hệ thống | E52: Hệ thống thông báo"Mật khẩu mới không trùng khớp" | F52: Hệ thống thông báo"Mật khẩu mới không trùng khớp" | G52: Passed | H52: 45955 | I52: Đức | J52: Passed | K52: 45959 | L52: Đức

Sheet Danh sách người dùng
A1: Project Name | B1: CoffeeGo-Nền tảng đặt bàn quán cà phê tích hợp AI Assistant và thanh toán điện tử
A2: Module Code | B2: Danh sách người dùng
B3: Hoàn thành | C3: Lỗi | D3: Chưa kiểm tra | E3: Bị chặn | F3: Tổng lần kiểm tra
A4: Round 1 | B4: =COUNTA(A35:A48)- 1 -> 13 | C4: =COUNTIF(G:G,"Failed") -> 0 | D4: =COUNTIF(G:G,"Untested") -> 0 | E4: =COUNTIF(G:G,"Blocked") -> 0 | F4: =B4 -> 13
A5: Round 2 | B5: =COUNTA(A42:A48) -> 7 | C5: =COUNTIF(J:J,"Failed") -> 0 | D5: =COUNTIF(J:J,"Untested") -> 0 | E5: =COUNTIF(J:J,"Blocked") -> 0 | F5: =B5 -> 7
A31: Test Case ID | B31: Mô tả | C31: Quy trình | D31: Điều kiện tiên quyết | E31: Kết quả mong đợi | F31: Kết quả thực tế | G31: Kết quả | M31: Chú thích
G32: Vòng 1 | J32: Vòng 2
G33: Trạng thái | H33: Ngày kiểm tra | I33: Người kiểm tra | J33: Trạng thái | K33: Ngày kiểm tra | L33: Người kiểm tra
A34: GUI_SHOW Danh sách người dùng
A35: GUI-DSND01 | B35: [Quản lý người dùng] Label | E35: -Label : black -Status : enable | F35: -Label : black -Status : enable | G35: Passed | H35: 45955 | I35: Huy | J35: Passed
A36: GUI-DSND02 | B36: [Tìm kiếm] Textbox | E36: -Label : black -Status : enable | F36: -Label : black -Status : enable | G36: Passed | H36: 45955 | I36: Huy | J36: Passed
A37: GUI-DSND03 | B37: [Tất cả ] Button | E37: -Label : white -Status : enable -Background:Green | F37: -Label : white -Status : enable -Background:Green | G37: Passed | H37: 45955 | I37: Huy | J37: Passed
A38: GUI-DSND04 | B38: [Nhân viên] Button | E38: -Label : white -Status : enable -Background:Blue | F38: -Label : white -Status : enable -Background:Blue | G38: Passed | H38: 45955 | I38: Huy | J38: Passed
A39: GUI-DSND05 | B39: [Admin] Button | E39: -Label : white -Status : enable -Background:red | F39: -Label : white -Status : enable -Background:red | G39: Passed | H39: 45955 | I39: Huy | J39: Passed
A40: GUI-DSND06 | B40: [Phân quyền] Button | E40: -Status: Enable | F40: -Status: Enable | G40: Passed | H40: 45955 | I40: Huy | J40: Passed
A41: FUNCTION_SHOW Danh sách người dùng
A42: FUNC-DSND01 | B42: Hiển thị danh sách người dùng | C42: 1. Truy cập vào trang web 2. Click: "Tài khoản" 3. Click: "Quản lý" 4. Click: "Quản lý người dùng" | D42: Đăng nhập thành công vào hệ thống | E42: Hệ thống hiển thị đúng thông tin đanh sách người dùng | F42: Hệ thống hiển thị đúng thông tin đanh sách người dùng | G42: Passed | H42: 45955 | I42: Huy | J42: Passed | K42: 45959 | L42: Huy
A43: FUNC-DSND02 | B43: Tìm kiếm theo email | C43: 1. Truy cập vào trang web 2. Click: "Tài khoản" 3. Click: "Quản lý" 4. Click: "Quản lý người dùng" 5. Click vào ô tìm kiếm 6. Nhập email người dùng | D43: Đăng nhập thành công vào hệ thống | E43: Hệ thống hiển thị người dùng cần tìm | F43: Hệ thống hiển thị người dùng cần tìm | G43: Passed | H43: 45955 | I43: Huy | J43: Passed | K43: 45959 | L43: Huy
A44: FUNC-DSND03 | B44: Tìm kiếm từ có trong tên | C44: 1. Truy cập vào trang web 2. Click: "Tài khoản" 3. Click: "Quản lý" 4. Click: "Quản lý người dùng" 5. Click vào ô tìm kiếm 6. Nhập 1 hoặc 2 ký tự | D44: Đăng nhập thành công vào hệ thống | E44: Hệ thống hiển thị người dùng có từ cần tìm | F44: Hệ thống hiển thị người dùng có từ cần tìm | G44: Passed | H44: 45955 | I44: Huy | J44: Passed | K44: 45959 | L44: Huy
A45: FUNC-DSND04 | B45: Mở giao diện phân quyền người dùng | C45: 1. Ở chức năng "Quản lý người dùng" 2. Click nút icon: "Phân quyền" | D45: Đăng nhập thành công vào hệ thống | E45: Hệ thống hiển thị giao diện phân quyền | F45: Hệ thống hiển thị giao diện phân quyền | G45: Passed | H45: 45955 | I45: Huy | J45: Passed | K45: 45959 | L45: Huy
A46: FUNC-DSND05 | B46: Click nút tất cả | C46: 1. Ở chức năng "Quản lý người dùng" 2. Click nút "Tất cả" | D46: Đăng nhập thành công vào hệ thống | E46: Hệ thống hiển thị danh sách tất cả người dùng có trong hệ thống | F46: Hệ thống hiển thị danh sách tất cả người dùng có trong hệ thống | G46: Passed | H46: 45955 | I46: Huy | J46: Passed | K46: 45959 | L46: Huy
A47: FUNC-DSND06 | B47: Click nút nhân viên | C47: 1. Ở chức năng "Quản lý người dùng" 2. Click nút "Nhân viên" | D47: Đăng nhập thành công vào hệ thống | E47: Hệ thống hiển thị đúng danh sách người dùng có vai trò là nhân viên | F47: Hệ thống hiển thị đúng danh sách người dùng có vai trò là nhân viên | G47: Passed | H47: 45955 | I47: Huy | J47: Passed | K47: 45959 | L47: Huy
A48: FUNC-DSND07 | B48: Click nút admin | C48: 1. Ở chức năng "Quản lý người dùng" 2. Click nút "Admin" | D48: Truy cập hệ thống | E48: Hệ thống hiển thị đúng danh sách người dùng có vai trò là admin | F48: Hệ thống hiển thị đúng danh sách người dùng có vai trò là admin | G48: Passed | H48: 45955 | I48: Huy | J48: Passed | K48: 45959 | L48: Huy

Sheet Phân quyền người dùng
A1: Project Name | B1: CoffeeGo-Nền tảng đặt bàn quán cà phê tích hợp AI Assistant và thanh toán điện tử
A2: Module Code | B2: Phân quyền người dùng
B3: Hoàn thành | C3: Lỗi | D3: Chưa kiểm tra | E3: Bị chặn | F3: Tổng lần kiểm tra
A4: Round 1 | B4: =COUNTA(A35:A44)- 1 -> 9 | C4: =COUNTIF(G:G,"Failed") -> 0 | D4: =COUNTIF(G:G,"Untested") -> 0 | E4: =COUNTIF(G:G,"Blocked") -> 0 | F4: =B4 -> 9
A5: Round 2 | B5: =COUNTA(A42:A44) -> 3 | C5: =COUNTIF(J:J,"Failed") -> 0 | D5: =COUNTIF(J:J,"Untested") -> 0 | E5: =COUNTIF(J:J,"Blocked") -> 0 | F5: =B5 -> 3
A31: Test Case ID | B31: Mô tả | C31: Quy trình | D31: Điều kiện tiên quyết | E31: Kết quả mong đợi | F31: Kết quả thực tế | G31: Kết quả | M31: Chú thích
G32: Vòng 1 | J32: Vòng 2
G33: Trạng thái | H33: Ngày kiểm tra | I33: Người kiểm tra | J33: Trạng thái | K33: Ngày kiểm tra | L33: Người kiểm tra
A34: GUI_SHOW Phân quyền người dùng
A35: GUI-PQ01 | B35: [Phân quyền người dùng] Label | E35: -Label : black -Status : enable | F35: -Label : black -Status : enable | G35: Passed | H35: 45955 | I35: Huy
A36: GUI-PQ02 | B36: [Tên người dùng] Label | E36: -Label : black -Status : enable | F36: -Label : black -Status : enable | G36: Passed | H36: 45955 | I36: Huy
A37: GUI-PQ03 | B37: [Email ] Label | E37: -Label : black -Status : enable | F37: -Label : black -Status : enable | G37: Passed | H37: 45955 | I37: Huy
A38: GUI-PQ04 | B38: [Vai trò] Combo box | E38: -Label : black -Status : enable | F38: -Label : black -Status : enable | G38: Passed | H38: 45955 | I38: Huy
A39: GUI-PQ05 | B39: [Hủy] Button | E39: -Text color :Black -Status : enable | F39: -Text color :Black -Status : enable | G39: Passed | H39: 45955 | I39: Huy
A40: GUI-PQ06 | B40: [Cập nhật] Button | E40: -Text color : white - Background color : Green -Status : enable | F40: -Text color : white - Background color : Green -Status : enable | G40: Passed | H40: 45955 | I40: Huy
A41: FUNCTION_SHOW Phân quyền người dùng
A42: FUNC-PQ01 | B42: Phân quyền người dùng thành công | C42: 1. Click"Quản lý người dùng" 2.Click :"Phân quyền" 3.Chọn vai trò"Admin" 4.click"Cập nhật" | D42: Đăng nhập thành công vào hệ thống và đã có ít nhất 1 tài khoản trong hệ thống | E42: Hệ thống thông báo "phân quyền thành công" | F42: Hệ thống thông báo "phân quyền thành công" và danh sách được cập nhật lại vai trò | G42: Passed | H42: 45955 | I42: Huy | J42: Passed | K42: 45959 | L42: Huy
A43: FUNC-PQ02 | B43: Click "Cập nhật" nhưng không thay đổi vai trò | C43: 1. Click"Quản lý người dùng" 2.Click :"Phân quyền" 3.Click vai trò"Nhân viên" 3.click"Hủy" | D43: Đăng nhập thành công vào hệ thống và đã có ít nhất 1 tài khoản trong hệ thống | E43: Hệ thống thông báo "phân quyền thành công" | F43: Hệ thống thông báo "phân quyền thành công" | G43: Passed | H43: 45955 | I43: Huy | J43: Passed | K43: 45959 | L43: Huy
A44: FUNC-PQ03 | B44: Click "Hủy" khi đã chọn vai trò | C44: 1. Click"Quản lý người dùng" 2.Click :"Phân quyền" 3.click"Cập nhật" | D44: Đăng nhập thành công vào hệ thống và đã có ít nhất 1 tài khoản trong hệ thống | E44: Giao diện phân quyền người dùng tắt và quay về danh sách người dùng mà không cập nhật vai trò | F44: Giao diện phân quyền người dùng tắt và quay về danh sách người dùng mà không cập nhật vai trò | G44: Passed | H44: 45955 | I44: Huy | J44: Passed | K44: 45959 | L44: Huy

Sheet Danh sách danh mục bài viết
A1: Project Name | B1: CoffeeGo-Nền tảng đặt bàn quán cà phê tích hợp AI Assistant và thanh toán điện tử
A2: Module Code | B2: Danh sách danh mục bài viết
B3: Hoàn thành | C3: Lỗi | D3: Chưa kiểm tra | E3: Bị chặn | F3: Tổng lần kiểm tra
A4: Round 1 | B4: =COUNTA(A35:A47)- 1 -> 12 | C4: =COUNTIF(G:G,"Failed") -> 0 | D4: =COUNTIF(G:G,"Untested") -> 0 | E4: =COUNTIF(G:G,"Blocked") -> 0 | F4: =B4 -> 12
A5: Round 2 | B5: =COUNTA(A41:A47) -> 7 | C5: =COUNTIF(J:J,"Failed") -> 0 | D5: =COUNTIF(J:J,"Untested") -> 0 | E5: =COUNTIF(J:J,"Blocked") -> 0 | F5: =B5 -> 7
A31: Test Case ID | B31: Mô tả | C31: Quy trình | D31: Điều kiện tiên quyết | E31: Kết quả mong đợi | F31: Kết quả thực tế | G31: Kết quả | M31: Chú thích
G32: Vòng 1 | J32: Vòng 2
G33: Trạng thái | H33: Ngày kiểm tra | I33: Người kiểm tra | J33: Trạng thái | K33: Ngày kiểm tra | L33: Người kiểm tra
A34: GUI_SHOW Quản lý danh mục bài viết
A35: GUI-QLDMBV01 | B35: [Thêm Danh Mục] Button | E35: - Text: white - Background: Green - Status:enable | F35: -Text: white -Background: Green -status:enable | G35: Passed | H35: 45956 | I35: Tấn
A36: GUI-QLDMBV02 | B36: [Quản lý danh mục] Label | E36: - Text: Black - Status: Enable | F36: -Text: Black -Trạng thái Enable | G36: Passed | H36: 45956 | I36: Tấn
A37: GUI-QLDMBV03 | B37: [Tìm Kiếm] TextBox | E37: - Status: Enable | F37: Status: Enable | G37: Passed | H37: 45956 | I37: Tấn
A38: GUI-QLDMBV04 | B38: [Edit] Button | E38: - Status: Enable | F38: - Status: Enable | G38: Passed | H38: 45956 | I38: Tấn
A39: GUI-QLDMBV05 | B39: [Delete] Button | E39: - Status: Enable | F39: - Status: Enable | G39: Passed | H39: 45956 | I39: Tấn
A40: FUNCTION_SHOW Quản lý danh mục bài viết
A41: FUNC-QLDMBV01 | B41: Hiển thị danh sách ban đầu | C41: Vào trang lần đầu | D41: API blogCategoryApi.getAll() hoạt động | E41: Hiển thị đúng STT, tên danh mục, slug, ngày tạo | F41: Hiển thị đúng STT, tên danh mục, slug, ngày tạo | G41: Passed | H41: 45956 | I41: Tấn | J41: Passed | K41: 45959 | L41: Tấn
A42: FUNC-QLDMBV02 | B42: Tìm kiếm theo tên | C42: Nhập tea vào ô tìm kiếm | D42: Đăng nhập admin thành công vào hệ thống | E42: Bảng sẽ hiển thị các danh mục có chứa tên tea, không phân biệt hoa thường | F42: Bảng sẽ hiển thị các danh mục có chứa tên tea, không phân biệt hoa thường | G42: Passed | H42: 45956 | I42: Tấn | J42: Passed | K42: 45959 | L42: Tấn
A43: FUNC-QLDMBV03 | B43: Mở modal thêm danh mục | C43: Click “Thêm danh mục” | D43: Đăng nhập admin thành công vào hệ thống | E43: Hiển thị UI thêm danh mục | F43: Hiển thị UI thêm danh mục | G43: Passed | H43: 45956 | I43: Tấn | J43: Passed | K43: 45959 | L43: Tấn
A44: FUNC-QLDMBV04 | B44: Mở UI cập nhật | C44: Click Edit danh mục bất kỳ | D44: Đăng nhập admin thành công vào hệ thống | E44: Hiển thị UI sửa tên danh mục vừa click | F44: Hiển thị UI sửa tên danh mục vừa click | G44: Passed | H44: 45956 | I44: Tấn | J44: Passed | K44: 45959 | L44: Tấn
A45: FUNC-QLDMBV05 | B45: Mở UI xóa danh mục | C45: Click Xóa ở danh mục bất kỳ | D45: Đăng nhập admin thành công vào hệ thống | E45: Hiển thị UI xóa danh mục | F45: Hiển thị UI xóa danh mục | G45: Passed | H45: 45956 | I45: Tấn | J45: Passed | K45: 45959 | L45: Tấn
A46: FUNC-QLDMBV06 | B46: Xóa Danh Mục thành công | C46: Xác nhận xóa danh mục | D46: Đăng nhập admin thành công vào hệ thống | E46: Hiển thị thông báo xóa danh mục thành công, reset lại phần hiển thị danh mục | F46: Hiển thị thông báo xóa danh mục thành công, reset lại phần hiển thị danh mục | G46: Passed | H46: 45956 | I46: Tấn | J46: Passed | K46: 45959 | L46: Tấn
A47: FUNC-QLDMBV07 | B47: Định dạng ngày tạo | C47: So sánh createdAt hiển thị | D47: Đăng nhập admin thành công vào hệ thống | E47: hiển thị theo chuẩn VN (dd/MM/yyyy HH:mm); không để ISO thô | F47: hiển thị theo chuẩn VN (dd/MM/yyyy HH:mm); không để ISO thô | G47: Passed | H47: 45956 | I47: Tấn | J47: Passed | K47: 45959 | L47: Tấn

Sheet Thêm danh mục bài viết
A1: Project Name | B1: CoffeeGo-Nền tảng đặt bàn quán cà phê tích hợp AI Assistant và thanh toán điện tử
A2: Module Code | B2: Thêm danh mục bài viết
B3: Hoàn thành | C3: Lỗi | D3: Chưa kiểm tra | E3: Bị chặn | F3: Tổng lần kiểm tra
A4: Round 1 | B4: =COUNTA(A35:A48)- 1 -> 13 | C4: =COUNTIF(G:G,"Failed") -> 0 | D4: =COUNTIF(G:G,"Untested") -> 0 | E4: =COUNTIF(G:G,"Blocked") -> 0 | F4: =B4 -> 13
A5: Round 2 | B5: =COUNTA(A42:A48) -> 7 | C5: =COUNTIF(J:J,"Failed") -> 0 | D5: =COUNTIF(J:J,"Untested") -> 0 | E5: =COUNTIF(J:J,"Blocked") -> 0 | F5: =B5 -> 7
A31: Test Case ID | B31: Mô tả | C31: Quy trình | D31: Điều kiện tiên quyết | E31: Kết quả mong đợi | F31: Kết quả thực tế | G31: Kết quả | M31: Chú thích
G32: Vòng 1 | J32: Vòng 2
G33: Trạng thái | H33: Ngày kiểm tra | I33: Người kiểm tra | J33: Trạng thái | K33: Ngày kiểm tra | L33: Người kiểm tra
A34: GUI_SHOW Thêm danh mục bài viết
A35: GUI-TDMBV01 | B35: [Thêm danh mục mới] Label | E35: Hiển thị “Thêm danh mục mới | F35: Hiển thị “Thêm danh mục mới | G35: Passed | H35: 45956 | I35: Tấn
A36: GUI-TDMBV02 | B36: [Tên Danh Mục] TextBox | E36: -Text: Black -Trạng thái Enable | F36: -Text: Black -Trạng thái Enable | G36: Passed | H36: 45956 | I36: Tấn
A37: GUI-TDMBV03 | B37: [Hủy] Button | E37: - Text: Black - Status: Enable, | F37: - Text: Black - Status: Enable, | G37: Passed | H37: 45956 | I37: Tấn
A38: GUI-TDMBV04 | B38: [Thêm Mới] Button | E38: -Text: Black -Trạng thái Enable | F38: -Text: Black -Trạng thái Enable | G38: Passed | H38: 45956 | I38: Tấn
A39: GUI-TDMBV05 | B39: App root & chặn scroll | C39: Mở UI Thêm danh mục | E39: Bị khóa cuộn trang khi mở UI Thêm danh mục | F39: Bị khóa cuộn trang khi mở UI Thêm danh mục | G39: Passed | H39: 45956 | I39: Tấn
A40: GUI-TDMBV06 | B40: [Tên danh Mục] Label | E40: - Text: Black - Status: Enable, | F40: - Text: Black - Status: Enable, | G40: Passed | H40: 45956 | I40: Tấn
A41: FUNCTION_SHOW Thêm danh mục bài viết
A42: FUNC-TDMBV01 | B42: Hiển thị UI thêm danh mục | D42: Đăng nhập admin thành công vào hệ thống | E42: Hiển thị đúng UI thêm danh mục | F42: Hiển thị đúng UI thêm danh mục | G42: Passed | H42: 45956 | I42: Tấn | J42: Passed | K42: 45959 | L42: Tấn
A43: FUNC-TDMBV02 | B43: Đóng UI Thêm danh mục | C43: Click nền tối hoặc nhấn ESC | D43: Đăng nhập admin thành công vào hệ thống | E43: Đóng UI thêm danh mục | F43: Đóng UI thêm danh mục | G43: Passed | H43: 45956 | I43: Tấn | J43: Passed | K43: 45959 | L43: Tấn
A44: FUNC-TDMBV03 | B44: Nhập tên danh mục vào textbox | C44: Gõ “tea” vào input | D44: Đăng nhập admin thành công vào hệ thống | E44: giá trị hiển thị trên textbox đúng | F44: giá trị hiển thị trên textbox đúng | G44: Passed | H44: 45956 | I44: Tấn | J44: Passed | K44: 45959 | L44: Tấn
A45: FUNC-TDMBV04 | B45: Validate rỗng khi tạo danh mục | C45: 1.Mở modal tạo, 2.để trống, 3.bấm Xác nhận | D45: Đăng nhập admin thành công vào hệ thống | E45: hiện toast lỗi “Tên danh mục không được để trống”; ui thêm danh mục vẫn mở. | F45: hiện toast lỗi “Tên danh mục không được để trống”; ui thêm danh mục vẫn mở. | G45: Passed | H45: 45956 | I45: Tấn | J45: Passed | K45: 45959 | L45: Tấn
A46: FUNC-TDMBV05 | B46: Tạo thành công | C46: 1.Nhập “Trà” → Xác nhận | D46: API create trả {_id,name} hợp lệ | E46: Tên danh mục được thêm vào data, hiển thị thông báo "thêm danh mục thành công", đóng UI thêm danh mục | F46: Tên danh mục được thêm vào data, hiển thị thông báo "thêm danh mục thành công", đóng UI thêm danh mục | G46: Passed | H46: 45956 | I46: Tấn | J46: Passed | K46: 45959 | L46: Tấn
A47: FUNC-TDMBV06 | B47: Tạo trùng tên danh mục | C47: Nhập “TEAHOLIC” (trùng) → Xác nhận | D47: API trả { message: "Danh mục đã tồn tại" } | E47: Hiện lỗi danh mục đã tồn tại | F47: Hiện lỗi danh mục đã tồn tại | G47: Passed | H47: 45956 | I47: Tấn | J47: Passed | K47: 45959 | L47: Tấn
A48: FUNC-TDMBV07 | B48: Ấn hủy | C48: Click Hủy | D48: Đăng nhập admin thành công vào hệ thống | E48: Đóng UI thêm danh mục | F48: Đóng UI thêm danh mục | G48: Passed | H48: 45956 | I48: Tấn | J48: Passed | K48: 45959 | L48: Tấn

Sheet Chỉnh sửa danh mục bài viết
A1: Project Name | B1: CoffeeGo-Nền tảng đặt bàn quán cà phê tích hợp AI Assistant và thanh toán điện tử
A2: Module Code | B2: Chỉnh sửa danh mục bài viết
B3: Hoàn thành | C3: Lỗi | D3: Chưa kiểm tra | E3: Bị chặn | F3: Tổng lần kiểm tra
A4: Round 1 | B4: =COUNTA(A35:A47)- 1 -> 12 | C4: =COUNTIF(G:G,"Failed") -> 0 | D4: =COUNTIF(G:G,"Untested") -> 0 | E4: =COUNTIF(G:G,"Blocked") -> 0 | F4: =B4 -> 12
A5: Round 2 | B5: =COUNTA(A42:A47) -> 6 | C5: =COUNTIF(J:J,"Failed") -> 0 | D5: =COUNTIF(J:J,"Untested") -> 0 | E5: =COUNTIF(J:J,"Blocked") -> 0 | F5: =B5 -> 6
A31: Test Case ID | B31: Mô tả | C31: Quy trình | D31: Điều kiện tiên quyết | E31: Kết quả mong đợi | F31: Kết quả thực tế | G31: Kết quả | M31: Chú thích
G32: Vòng 1 | J32: Vòng 2
G33: Trạng thái | H33: Ngày kiểm tra | I33: Người kiểm tra | J33: Trạng thái | K33: Ngày kiểm tra | L33: Người kiểm tra
A34: GUI_SHOW chỉnh sửa danh mục bài viết
A35: GUI-CNDMBV01 | B35: [Cập nhật danh mục] Label | E35: Hiển thị “Cập nhật danh mục" | F35: Hiển thị “Cập nhật danh mục" | G35: Passed | H35: 45956 | I35: Tấn | J35: Passed
A36: GUI-CNDMBV02 | B36: [Tên Danh Mục] TextBox | E36: -Text: Black -Trạng thái Enable | F36: -Text: Black -Trạng thái Enable | G36: Passed | H36: 45956 | I36: Tấn | J36: Passed
A37: GUI-CNDMBV03 | B37: [Hủy] Button | E37: - Text: Black - Status: Enable, | F37: - Text: Black - Status: Enable, | G37: Passed | H37: 45956 | I37: Tấn | J37: Passed
A38: GUI-CNDMBV04 | B38: [Cập nhật] Button | E38: -Text: Black -Trạng thái Enable | F38: -Text: Black -Trạng thái Enable | G38: Passed | H38: 45956 | I38: Tấn | J38: Passed
A39: GUI-CNDMBV05 | B39: App root & chặn scroll | C39: Mở UI Thêm danh mục | E39: Bị khóa cuộn trang khi mở UI Thêm danh mục | F39: Bị khóa cuộn trang khi mở UI Thêm danh mục | G39: Passed | H39: 45956 | I39: Tấn | J39: Passed
A40: GUI-CNDMBV06 | B40: [Tên danh mục] Label | E40: - Text: Black - Status: Enable, | F40: - Text: Black - Status: Enable, | G40: Passed | H40: 45956 | I40: Tấn | J40: Passed
A41: FUNCTION_SHOW chỉnh sửa danh mục bài viết
A42: FUNC-CNDMBV01 | B42: Mở UI Cập nhật danh mục | D42: Đã có danh mục bài viết trên hệ thống | E42: UI hiển thị đúng, bị khóa cuộn chuột | F42: UI hiển thị đúng, bị khóa cuộn chuột | G42: Passed | H42: 45956 | I42: Tấn | J42: Passed | K42: 45959 | L42: Tấn
A43: FUNC-QLGH02 | B43: Đóng UI Cập nhật danh mục | C43: Click nền tối hoặc nhấn ESC, | D43: Đã có danh mục bài viết trên hệ thống | E43: Đóng UI cập nhật danh mục | F43: Đóng UI cập nhật danh mục | G43: Passed | H43: 45956 | I43: Tấn | J43: Passed | K43: 45959 | L43: Tấn
A44: FUNC-QLGH03 | B44: Ấn hủy | C44: Click Hủy | D44: Đã có danh mục bài viết trên hệ thống | E44: Đóng UI cập nhật danh mục | F44: Đóng UI cập nhật danh mục | G44: Passed | H44: 45956 | I44: Tấn | J44: Passed | K44: 45959 | L44: Tấn
A45: FUNC-QLGH04 | B45: Nhập tên mới vào input | C45: Gõ “Chuyện Trà” | D45: Đã có danh mục bài viết trên hệ thống | E45: input hiển thị đúng | F45: input hiển thị đúng | G45: Passed | H45: 45956 | I45: Tấn | J45: Passed | K45: 45959 | L45: Tấn
A46: FUNC-QLGH05 | B46: Disable nút cập nhật | C46: Xóa hết text trong input | D46: Đã có danh mục bài viết trên hệ thống | E46: Nút Cập nhật chuyển sang trạng thái disabled | F46: Nút Cập nhật chuyển sang trạng thái disabled | G46: Passed | H46: 45956 | I46: Tấn | J46: Passed | K46: 45959 | L46: Tấn
A47: FUNC-QLGH06 | B47: Cập nhật tên danh mục thành công | C47: 1.Trong UI sửa TEAHOLIC 2.Nhập thành TEA 3.Ấn Xác Nhận | D47: Đã có danh mục bài viết trên hệ thống | E47: Hiển thị thông báo cập nhật danh mục thành công, đóng UI | F47: Hiển thị thông báo cập nhật danh mục thành công, đóng UI | G47: Passed | H47: 45956 | I47: Tấn | J47: Passed | K47: 45959 | L47: Tấn

Sheet Danh sách bài viết
A1: Project Name | B1: CoffeeGo-Nền tảng đặt bàn quán cà phê tích hợp AI Assistant và thanh toán điện tử
A2: Module Code | B2: Danh sách bài viết
B3: Hoàn thành | C3: Lỗi | D3: Chưa kiểm tra | E3: Bị chặn | F3: Tổng lần kiểm tra
A4: Round 1 | B4: =COUNTA(A35:A50)- 1 -> 15 | C4: =COUNTIF(G:G,"Failed") -> 0 | D4: =COUNTIF(G:G,"Untested") -> 0 | E4: =COUNTIF(G:G,"Blocked") -> 0 | F4: =B4 -> 15
A5: Round 2 | B5: =COUNTA(A42:A50) -> 9 | C5: =COUNTIF(J:J,"Failed") -> 0 | D5: =COUNTIF(J:J,"Untested") -> 0 | E5: =COUNTIF(J:J,"Blocked") -> 0 | F5: =B5 -> 9
A31: Test Case ID | B31: Mô tả | C31: Quy trình | D31: Điều kiện tiên quyết | E31: Kết quả mong đợi | F31: Kết quả thực tế | G31: Kết quả | M31: Chú thích
G32: Vòng 1 | J32: Vòng 2
G33: Trạng thái | H33: Ngày kiểm tra | I33: Người kiểm tra | J33: Trạng thái | K33: Ngày kiểm tra | L33: Người kiểm tra
A34: GUI_SHOW Danh sách bài viết
A35: GUI - DSBV01 | B35: [Quản lý công thức] heading | E35: - Text: Black - Status: Enable | F35: - Text: Black - Status: Enable | G35: Passed | H35: 45956 | I35: Khánh
A36: GUI - DSBV02 | B36: [Thêm công thức] Button | E36: -Text color : white - Background color : green - Hover: + background color: green -Status : enable | F36: -Text color : white - Background color : green - Hover: + background color: green -Status : enable | G36: Passed | H36: 45956 | I36: Khánh
A37: GUI - DSBV03 | B37: [Tìm kiếm] Input | E37: -Text color : grey - Background color : transparent -Status : enable | F37: -Text color : grey - Background color : transparent -Status : enable | G37: Passed | H37: 45956 | I37: Khánh
A38: GUI - DSBV04 | B38: [Chỉnh sửa bài viết] Button | E38: -Text color : blue - Hover: Text color :#007fff -Status : enable | F38: -Text color : blue - Hover: Text color :#007fff -Status : enable | G38: Passed | H38: 45956 | I38: Khánh
A39: GUI - DSBV05 | B39: [Xóa bài viết] Button | E39: -Text color : #ff2400 - Hover: red -Status : enable | F39: -Text color : #ff2400 - Hover: red -Status : enable | G39: Passed | H39: 45956 | I39: Khánh
A40: GUI - DSBV06 | B40: [Xem bài viết] Button | E40: -Text color : #007fff - Hover: Text color :blue -Status : enable | F40: -Text color : #007fff - Hover: Text color :blue -Status : enable | G40: Passed | H40: 45956 | I40: Khánh
A41: FUNCTION_SHOW Danh sách bài viết
A42: FUNC-DSBV01 | B42: Hiển thị danh sách bài viết | C42: 1. Truy cập vào trang web 2. Click: "Tài khoản" 3. Click: "Quản lý" 4. Click: "Quản lý công thức" | D42: Đăng nhập thành công vào hệ thống | E42: Hệ thống hiển thị đúng thông tin danh sách bài viết | F42: Hệ thống hiển thị đúng thông tin danh sách bài viết | G42: Passed | H42: 45956 | I42: Khánh | J42: Passed | K42: 45959 | L42: Khánh
A43: FUNC-DSBV02 | B43: Tìm kiếm theo tên | C43: 1. Truy cập vào trang web 2. Click: "Tài khoản" 3. Click: "Quản lý" 4. Click: "Quản lý bài viết" | D43: Đăng nhập thành công vào hệ thống | E43: Hệ thống hiển thị bài viết cần tìm | F43: Hệ thống hiển thị bài viết cần tìm | G43: Passed | H43: 45956 | I43: Khánh | J43: Passed | K43: 45959 | L43: Khánh
A44: FUNC-DSBV03 | B44: Tìm kiếm từ có trong tên | C44: 1. Truy cập vào trang web 2. Click: "Tài khoản" 3. Click: "Quản lý" 4. Click: "Quản lý bài viết" 5. Click vào ô tìm kiếm | D44: Đăng nhập thành công vào hệ thống | E44: Hệ thống hiển thị bài viết cần tìm | F44: Hệ thống hiển thị bài viết cần tìm | G44: Passed | H44: 45956 | I44: Khánh | J44: Passed | K44: 45959 | L44: Khánh
A45: FUNC-DSBV04 | B45: Mở giao diện thêm bài viết | C45: 1. Ở chức năng "Quản lý bài viết" 2. Click: "Thêm công thức" | D45: Đăng nhập thành công vào hệ thống | E45: Hệ thống hiển thị đúng giao diện thêm bài viết | F45: Hệ thống hiển thị đúng giao diện thêm bài viết | G45: Passed | H45: 45956 | I45: Khánh | J45: Passed | K45: 45959 | L45: Khánh
A46: FUNC-DSBV05 | B46: Mở giao diện chỉnh sửa | C46: 1. Ở chức năng "Quản lý bài viết" 2. Click vào ô biểu tượng chỉnh sửa | D46: Đăng nhập thành công vào hệ thống | E46: Hệ thống hiển thị đúng giao diện chỉnh sửa bài viết | F46: Hệ thống hiển thị đúng giao diện chỉnh sửa bài viết | G46: Passed | H46: 45956 | I46: Khánh | J46: Passed | K46: 45959 | L46: Khánh
A47: FUNC-DSBV06 | B47: Mở giao diện xóa bài viết | C47: 1. Ở chức năng "Quản lý bài viết" 2. Click vào ô biểu tượng xóa | D47: Đăng nhập thành công vào hệ thống | E47: Hệ thống hiển thị ô xác nhận xóa | F47: Hệ thống hiển thị ô xác nhận xóa | G47: Passed | H47: 45956 | I47: Khánh | J47: Passed | K47: 45959 | L47: Khánh
A48: FUNC-DSBV07 | B48: Xóa công thức thành công | C48: 1. Ở chức năng "Quản lý bài viết" 2. Click vào ô biểu tượng xóa 3. Click: "Xóa" | D48: Đăng nhập thành công vào hệ thống | E48: -Hệ thống xóa thành công bài viết -Hệ thống hiển thông báo xóa thành công - Hệ thống tải lại trang sau khi xóa công thức | F48: -Hệ thống xóa thành công bài viết -Hệ thống hiển thông báo xóa thành công - Hệ thống tải lại trang sau khi xóa công thức | G48: Passed | H48: 45956 | I48: Khánh | J48: Passed | K48: 45959 | L48: Khánh
A49: FUNC-DSBV08 | B49: Hủy xóa bài viết | C49: 1. Ở chức năng "Quản lý bài viết" 2. Click vào ô biểu tượng xóa 3. Click: "Hủy" | D49: Đăng nhập thành công vào hệ thống | E49: Hệ thống quay lại giao diện danh sách bài viết mà không có bất cứ thay đổi nào | F49: Hệ thống quay lại giao diện danh sách bài viết mà không có bất cứ thay đổi nào | G49: Passed | H49: 45956 | I49: Khánh | J49: Passed | K49: 45959 | L49: Khánh
A50: FUNC-DSBV09 | B50: Định dạng ngày tạo | C50: 1. Truy cập vào trang web 2. Click: "Tài khoản" 3. Click: "Quản lý" 4. Click: "Quản lý bài viết" | D50: Đăng nhập thành công vào hệ thống | E50: Hiển thị thời gian theo chuẩn: hh:mm:ss dd/mm/yyyy | F50: Hiển thị thời gian theo chuẩn: hh:mm:ss dd/mm/yyyy | G50: Passed | H50: 45956 | I50: Khánh | J50: Passed | K50: 45959 | L50: Khánh

Sheet Thêm bài viết
A1: Project Name | B1: CoffeeGo-Nền tảng đặt bàn quán cà phê tích hợp AI Assistant và thanh toán điện tử
A2: Module Code | B2: Thêm bài viết
B3: Hoàn thành | C3: Lỗi | D3: Chưa kiểm tra | E3: Bị chặn | F3: Tổng lần kiểm tra
A4: Round 1 | B4: =COUNTA(A35:A54)- 1 -> 19 | C4: =COUNTIF(G:G,"Failed") -> 0 | D4: =COUNTIF(G:G,"Untested") -> 0 | E4: =COUNTIF(G:G,"Blocked") -> 0 | F4: =B4 -> 19
A5: Round 2 | B5: =COUNTA(A42:A54) -> 13 | C5: =COUNTIF(J:J,"Failed") -> 0 | D5: =COUNTIF(J:J,"Untested") -> 0 | E5: =COUNTIF(J:J,"Blocked") -> 0 | F5: =B5 -> 13
A31: Test Case ID | B31: Mô tả | C31: Quy trình | D31: Điều kiện tiên quyết | E31: Kết quả mong đợi | F31: Kết quả thực tế | G31: Kết quả | M31: Chú thích
G32: Vòng 1 | J32: Vòng 2
G33: Trạng thái | H33: Ngày kiểm tra | I33: Người kiểm tra | J33: Trạng thái | K33: Ngày kiểm tra | L33: Người kiểm tra
A34: GUI_SHOW Thêm bài viết
A35: GUI-TBV01 | B35: [Tiêu đề] Label | E35: -Text: Black -Trạng thái Enable | F35: -Text: Black -Trạng thái Enable | G35: Passed | H35: 45956 | I35: Khánh | J35: Passed
A36: GUI-TBV02 | B36: [Tên mục] Text | E36: -Text: Black -Trạng thái Enable | F36: -Text: Black -Trạng thái Enable | G36: Passed | H36: 45956 | I36: Khánh | J36: Passed
A37: GUI-TBV03 | B37: [Ô nhập dữ liệu] Input | E37: -Text color : green - Border: Solid black - Status: Enable | F37: -Text color : green - Border: Solid black - Status: Enable | G37: Passed | H37: 45956 | I37: Khánh | J37: Passed
A38: GUI-TBV04 | B38: [DropDown danh mục] Select | E38: -Text color : Black - Border: Solid black - Status: Enable | F38: -Text color : Black - Border: Solid black - Status: Enable | G38: Passed | H38: 45956 | I38: Khánh | J38: Passed
A39: GUI-TBV05 | B39: [Hủy] Button | E39: -Text color: Black -Backround: White - Border: Solid black -Status: Enable | F39: -Text color: Black -Backround: White - Border: Solid black -Status: Enable | G39: Passed | H39: 45956 | I39: Khánh | J39: Passed
A40: GUI-TBV06 | B40: [Thêm mới] Button | E40: -Text color: White -Backround: green - Border: None -Status: Enable | F40: -Text color: White -Backround: green - Border: None -Status: Enable | G40: Passed | H40: 45956 | I40: Khánh | J40: Passed
A41: FUNCTION_SHOW Thêm bài viết
